Workbook

Sheet Stock po Resolutor
A3: Cuenta de Número de Expediente | B3: Etiquetas de columna
B4: 2020 | C4: 2022 | D4: 2023 | E4: 2024 | F4: 2025 | G4: Total general
A6: Etiquetas de fila
A7: Alberto Anthar Munive Bisetti | B7: 2 | G7: 2
A8: CARLOS ALFREDO, MALAGA PORTOCARRERO | D8: 1 | F8: 24 | G8: 25
A9: CECILIA JACQUELINE, ACOSTA SALAZAR | B9: 8 | C9: 2 | F9: 31 | G9: 41
A10: ENRIQUE ALVARO, VILLANUEVA HURTADO | D10: 1 | G10: 1
A11: JOSE WAGNER, LINAREZ AMACIFUEN | F11: 36 | G11: 36
A12: JUAN CARLOS, CUYA VELARDE | F12: 28 | G12: 28
A13: LOURDES FABIOLA, PRETEL NOBLECILLA | B13: 6 | D13: 1 | E13: 1 | F13: 40 | G13: 48
A14: LYDIA CAROLINA, ARESTEGUI PEREYRA | C14: 1 | D14: 1 | F14: 41 | G14: 43
A15: POUL CRISTIAN, VALDIVIA CHARCA | E15: 1 | F15: 31 | G15: 32
A16: RENIERD, RIOS GOMEZ | F16: 28 | G16: 28
A17: RICHARD, VELA NUÑEZ | C17: 1 | D17: 1 | F17: 42 | G17: 44
A18: ROBERTO CESAR, RIVAROLA HIDALGO | F18: 42 | G18: 42
A19: VICTORIA CARMEN ROSA, FLORES ALVITEZ | D19: 1 | F19: 45 | G19: 46
A20: WILDER ELOY, ULLOA ASCENCIO | C20: 1 | F20: 45 | G20: 46
A21: YESSENIA LIZET, SALCEDO DIAZ | F21: 1 | G21: 1
A22: Total general | B22: 16 | C22: 5 | D22: 6 | E22: 2 | F22: 434 | G22: 463

Sheet Stock Reclamo
A1: Indicador de OEA | B1: Tipo de documento | C1: Número documento | D1: Nombre o Razón Social | E1: Número de Expediente | F1: Fecha de Presentación | G1: Plazo TLT | H1: Fecha_vencimiento | I1: Etapa del Recurso | J1: Resolutor asignado | K1: Supervisor | L1: División | M1: Observaciones
A2: NO | B2: RUC | C2: 20555881801 | D2: INCAVO S.A.C. | E2: 4090340004637 | F2: 44099 | G2: 125 | H2: 44279 | I2: RECURSO EN ANÁLISIS DE FONDO | J2: CECILIA JACQUELINE, ACOSTA SALAZAR | K2: ALBERTO ANTHAR, MUNIVE BISETTI | L2: ROBERTO GABRIEL, VERA TUDELA GALLESI | M2: No Gestionable
A3: NO | B3: RUC | C3: 20555881801 | D3: INCAVO S.A.C. | E3: 4090340004646 | F3: 44099 | G3: 125 | H3: 44279 | I3: RECURSO EN ANÁLISIS DE FONDO | J3: CECILIA JACQUELINE, ACOSTA SALAZAR | K3: ALBERTO ANTHAR, MUNIVE BISETTI | L3: ROBERTO GABRIEL, VERA TUDELA GALLESI | M3: No Gestionable
A4: NO | B4: RUC | C4: 20555881801 | D4: INCAVO S.A.C. | E4: 4090340004651 | F4: 44099 | G4: 125 | H4: 44279 | I4: RECURSO EN ANÁLISIS DE FONDO | J4: LOURDES FABIOLA, PRETEL NOBLECILLA | K4: ALBERTO ANTHAR, MUNIVE BISETTI | L4: ROBERTO GABRIEL, VERA TUDELA GALLESI | M4: No Gestionable
A5: NO | B5: RUC | C5: 20555881801 | D5: INCAVO S.A.C. | E5: 4090340004652 | F5: 44099 | G5: 125 | H5: 44279 | I5: RECURSO EN ANÁLISIS DE FONDO | J5: LOURDES FABIOLA, PRETEL NOBLECILLA | K5: ALBERTO ANTHAR, MUNIVE BISETTI | L5: ROBERTO GABRIEL, VERA TUDELA GALLESI | M5: No Gestionable
A6: NO | B6: RUC | C6: 20555881801 | D6: INCAVO S.A.C. | E6: 4090340004656 | F6: 44099 | G6: 125 | H6: 44279 | I6: RECURSO EN ANÁLISIS DE FONDO | J6: CECILIA JACQUELINE, ACOSTA SALAZAR | K6: ALBERTO ANTHAR, MUNIVE BISETTI | L6: ROBERTO GABRIEL, VERA TUDELA GALLESI | M6: No Gestionable
A7: NO | B7: RUC | C7: 20555881801 | D7: INCAVO S.A.C. | E7: 4090340004662 | F7: 44099 | G7: 125 | H7: 44279 | I7: RECURSO EN ANÁLISIS DE FONDO | J7: CECILIA JACQUELINE, ACOSTA SALAZAR | K7: ALBERTO ANTHAR, MUNIVE BISETTI | L7: ROBERTO GABRIEL, VERA TUDELA GALLESI | M7: No Gestionable
A8: NO | B8: RUC | C8: 20555881801 | D8: INCAVO S.A.C. | E8: 4090340004663 | F8: 44099 | G8: 125 | H8: 44279 | I8: RECURSO EN ANÁLISIS DE FONDO | J8: LOURDES FABIOLA, PRETEL NOBLECILLA | K8: ALBERTO ANTHAR, MUNIVE BISETTI | L8: ROBERTO GABRIEL, VERA TUDELA GALLESI | M8: No Gestionable
A9: NO | B9: RUC | C9: 20555881801 | D9: INCAVO S.A.C. | E9: 4090340004667 | F9: 44099 | G9: 125 | H9: 44279 | I9: RECURSO EN ANÁLISIS DE FONDO | J9: Alberto Anthar Munive Bisetti | K9: ALBERTO ANTHAR, MUNIVE BISETTI | L9: ROBERTO GABRIEL, VERA TUDELA GALLESI | M9: No Gestionable
A10: NO | B10: RUC | C10: 20555881801 | D10: INCAVO S.A.C. | E10: 4090340004668 | F10: 44099 | G10: 125 | H10: 44279 | I10: RECURSO EN ANÁLISIS DE FONDO | J10: Alberto Anthar Munive Bisetti | K10: ALBERTO ANTHAR, MUNIVE BISETTI | L10: ROBERTO GABRIEL, VERA TUDELA GALLESI | M10: No Gestionable
A11: NO | B11: RUC | C11: 20555881801 | D11: INCAVO S.A.C. | E11: 4090340004670 | F11: 44099 | G11: 125 | H11: 44279 | I11: RECURSO EN ANÁLISIS DE FONDO | J11: CECILIA JACQUELINE, ACOSTA SALAZAR | K11: ALBERTO ANTHAR, MUNIVE BISETTI | L11: ROBERTO GABRIEL, VERA TUDELA GALLESI | M11: No Gestionable
A12: NO | B12: RUC | C12: 20555881801 | D12: INCAVO S.A.C. | E12: 4090340004672 | F12: 44099 | G12: 125 | H12: 44279 | I12: RECURSO EN ANÁLISIS DE FONDO | J12: CECILIA JACQUELINE, ACOSTA SALAZAR | K12: ALBERTO ANTHAR, MUNIVE BISETTI | L12: ROBERTO GABRIEL, VERA TUDELA GALLESI | M12: No Gestionable
A13: NO | B13: RUC | C13: 20555881801 | D13: INCAVO S.A.C. | E13: 4090340004677 | F13: 44099 | G13: 125 | H13: 44279 | I13: RECURSO EN ANÁLISIS DE FONDO | J13: LOURDES FABIOLA, PRETEL NOBLECILLA | K13: ALBERTO ANTHAR, MUNIVE BISETTI | L13: ROBERTO GABRIEL, VERA TUDELA GALLESI | M13: No Gestionable
... A31: NO | B31: RUC | C31: 10180119481 | D31: CRUZADO CHAFFO SALVADOR ENRIQUE | E31: 4090340016030 | F31: 45702 | G31: 125 | H31: 45888 | I31: RECURSO EN ANÁLISIS DE FONDO | J31: VICTORIA CARMEN ROSA, FLORES ALVITEZ | K31: ALBERTO ANTHAR, MUNIVE BISETTI | L31: ROBERTO GABRIEL, VERA TUDELA GALLESI | M31: I-1297584 pendiente .Resuelto RD 4090140015549
A32: NO | B32: RUC | C32: 20609732718 | D32: SERVISORTEK S.A.C. | E32: 4090340016420 | F32: 45722 | G32: 125 | H32: 45908 | I32: RECURSO EN ANÁLISIS DE FONDO | J32: RICHARD, VELA NUÑEZ | K32: JUAN CARLOS, CUYA VELARDE | L32: ROBERTO GABRIEL, VERA TUDELA GALLESI
A33: NO | B33: RUC | C33: 20512898891 | D33: AGENCIA DE ADUANA VILCAPOMA HERMANOS SOCIEDAD COMERCIAL DE RESPONSABILIDAD LIMITADA | E33: 4090340016100 | F33: 45723 | G33: 125 | H33: 45909 | I33: RECURSO EN ANÁLISIS DE FONDO | J33: RICHARD, VELA NUÑEZ | K33: JUAN CARLOS, CUYA VELARDE | L33: ROBERTO GABRIEL, VERA TUDELA GALLESI
A34: NO | B34: RUC | C34: 20601226015 | D34: AGROCASAGRANDE S.A.C. | E34: 4090340016183 | F34: 45728 | G34: 125 | H34: 45912 | I34: RECURSO EN ANÁLISIS DE FONDO | J34: LYDIA CAROLINA, ARESTEGUI PEREYRA | K34: ALBERTO ANTHAR, MUNIVE BISETTI | L34: ROBERTO GABRIEL, VERA TUDELA GALLESI
A35: NO | B35: RUC | C35: 20521770814 | D35: PERU CUSTOMS ADVISER S.A.C. | E35: 4090340016196 | F35: 45730 | G35: 125 | H35: 45916 | I35: RECURSO EN ANÁLISIS DE FONDO | J35: CECILIA JACQUELINE, ACOSTA SALAZAR | K35: ALBERTO ANTHAR, MUNIVE BISETTI | L35: ROBERTO GABRIEL, VERA TUDELA GALLESI
A36: NO | B36: RUC | C36: 10453654856 | D36: AGUILAR TOMAPASCA ESTRELLA ELIZABET | E36: 4090340016221 | F36: 45730 | G36: 125 | H36: 45916 | I36: RECURSO EN ANÁLISIS DE FONDO | J36: LYDIA CAROLINA, ARESTEGUI PEREYRA | K36: ALBERTO ANTHAR, MUNIVE BISETTI | L36: ROBERTO GABRIEL, VERA TUDELA GALLESI
A37: NO | B37: RUC | C37: 20333363900 | D37: ENGIE ENERGIA PERU S.A. | E37: 4090340016198 | F37: 45733 | G37: 125 | H37: 45917 | I37: RECURSO EN ANÁLISIS DE FONDO | J37: CECILIA JACQUELINE, ACOSTA SALAZAR | K37: ALBERTO ANTHAR, MUNIVE BISETTI | L37: ROBERTO GABRIEL, VERA TUDELA GALLESI
A38: NO | B38: RUC | C38: 20604180229 | D38: MADERACRE TIMBER S.A.C. | E38: 4090340016207 | F38: 45733 | G38: 125 | H38: 45917 | I38: RECURSO EN ANÁLISIS DE FONDO | J38: ROBERTO CESAR, RIVAROLA HIDALGO | K38: JUAN CARLOS, CUYA VELARDE | L38: ROBERTO GABRIEL, VERA TUDELA GALLESI
A39: NO | B39: RUC | C39: 20604180229 | D39: MADERACRE TIMBER S.A.C. | E39: 4090340016209 | F39: 45733 | G39: 125 | H39: 45917 | I39: RECURSO EN ANÁLISIS DE FONDO | J39: ROBERTO CESAR, RIVAROLA HIDALGO | K39: JUAN CARLOS, CUYA VELARDE | L39: ROBERTO GABRIEL, VERA TUDELA GALLESI
A40: NO | B40: RUC | C40: 20604180229 | D40: MADERACRE TIMBER S.A.C. | E40: 4090340016210 | F40: 45733 | G40: 125 | H40: 45917 | I40: RECURSO EN ANÁLISIS DE FONDO | J40: ROBERTO CESAR, RIVAROLA HIDALGO | K40: JUAN CARLOS, CUYA VELARDE | L40: ROBERTO GABRIEL, VERA TUDELA GALLESI
A41: NO | B41: RUC | C41: 20604180229 | D41: MADERACRE TIMBER S.A.C. | E41: 4090340016211 | F41: 45733 | G41: 125 | H41: 45917 | I41: RECURSO EN ANÁLISIS DE FONDO | J41: ROBERTO CESAR, RIVAROLA HIDALGO | K41: JUAN CARLOS, CUYA VELARDE | L41: ROBERTO GABRIEL, VERA TUDELA GALLESI
A42: NO | B42: CI | C42: 202168086 | D42: SOUBLETTE TAMANI NICOLAS ESTEBAN | E42: 4090340016248 | F42: 45733 | G42: 125 | H42: 45917 | I42: RECURSO EN ANÁLISIS DE FONDO | J42: RICHARD, VELA NUÑEZ | K42: JUAN CARLOS, CUYA VELARDE | L42: ROBERTO GABRIEL, VERA TUDELA GALLESI
A43: NO | B43: RUC | C43: 20554886575 | D43: SERVICIOS GENERALES DE IMPORTACION Y EXPORTACION HIK SOCIEDAD ANONIMA CERRADA | E43: 4090340016223 | F43: 45734 | G43: 125 | H43: 45918 | I43: RECURSO EN ANÁLISIS DE FONDO | J43: LYDIA CAROLINA, ARESTEGUI PEREYRA | K43: ALBERTO ANTHAR, MUNIVE BISETTI | L43: ROBERTO GABRIEL, VERA TUDELA GALLESI
... A59: NO | B59: RUC | C59: 20132272418 | D59: INTERNACIONAL DE TRANSPORTE TURISTICO Y SERVICIOS SRL | E59: 4090340016465 | F59: 45749 | G59: 125 | H59: 45933 | I59: RECURSO EN ANÁLISIS DE FONDO | J59: ROBERTO CESAR, RIVAROLA HIDALGO | K59: JUAN CARLOS, CUYA VELARDE | L59: ROBERTO GABRIEL, VERA TUDELA GALLESI
A60: NO | B60: RUC | C60: 10432083158 | D60: RENGIFO BAZAN MILTON FREDY | E60: 4090340016649 | F60: 45749 | G60: 125 | H60: 45933 | I60: RECURSO EN ANÁLISIS DE FONDO | J60: JUAN CARLOS, CUYA VELARDE | K60: JUAN CARLOS, CUYA VELARDE | L60: ROBERTO GABRIEL, VERA TUDELA GALLESI | M60: SCAD 250279 RD 4090140015663
A61: NO | B61: RUC | C61: 20390605235 | D61: PHONIX WORLD S.A.C | E61: 4090340016456 | F61: 45750 | G61: 125 | H61: 45936 | I61: RECURSO EN ANÁLISIS DE FONDO | J61: CECILIA JACQUELINE, ACOSTA SALAZAR | K61: ALBERTO ANTHAR, MUNIVE BISETTI | L61: ROBERTO GABRIEL, VERA TUDELA GALLESI
A62: NO | B62: RUC | C62: 20603055731 | D62: NK WINNERS COMPANY S.A.C. | E62: 4090340016457 | F62: 45750 | G62: 125 | H62: 45936 | I62: RECURSO EN ANÁLISIS DE FONDO | J62: CARLOS ALFREDO, MALAGA PORTOCARRERO | K62: JUAN CARLOS, CUYA VELARDE | L62: ROBERTO GABRIEL, VERA TUDELA GALLESI
A63: NO | B63: RUC | C63: 20601311781 | D63: RICBEL F.H. LOGISTICA S.A. | E63: 4090340016467 | F63: 45751 | G63: 125 | H63: 45937 | I63: RECURSO EN ANÁLISIS DE FONDO | J63: WILDER ELOY, ULLOA ASCENCIO | K63: ALBERTO ANTHAR, MUNIVE BISETTI | L63: ROBERTO GABRIEL, VERA TUDELA GALLESI
A64: NO | B64: PASAPORTE | C64: FK194435 | D64: BIANCA CASTANHOLA | E64: 4090340017313 | F64: 45751 | G64: 125 | H64: 45937 | I64: RECURSO EN ANÁLISIS DE FONDO | J64: RICHARD, VELA NUÑEZ | K64: JUAN CARLOS, CUYA VELARDE | L64: ROBERTO GABRIEL, VERA TUDELA GALLESI
A65: NO | B65: RUC | C65: 20565510348 | D65: ACCIONES VETERINARIAS E.I.R.L. | E65: 4090340017263 | F65: 45754 | G65: 125 | H65: 45939 | I65: RECURSO EN ANÁLISIS DE FONDO | J65: WILDER ELOY, ULLOA ASCENCIO | K65: ALBERTO ANTHAR, MUNIVE BISETTI | L65: ROBERTO GABRIEL, VERA TUDELA GALLESI
A66: NO | B66: RUC | C66: 10483996191 | D66: AMARO ARONI OLGA | E66: 4090340016801 | F66: 45755 | G66: 125 | H66: 45940 | I66: RECURSO EN ANÁLISIS DE FONDO | J66: RICHARD, VELA NUÑEZ | K66: JUAN CARLOS, CUYA VELARDE | L66: ROBERTO GABRIEL, VERA TUDELA GALLESI
A67: NO | B67: RUC | C67: 20608543270 | D67: IMPORT & EXPORT JEZABELL FASHION E.I.R.L. | E67: 4090340016532 | F67: 45756 | G67: 125 | H67: 45943 | I67: RECURSO EN ANÁLISIS DE FONDO | J67: LYDIA CAROLINA, ARESTEGUI PEREYRA | K67: ALBERTO ANTHAR, MUNIVE BISETTI | L67: ROBERTO GABRIEL, VERA TUDELA GALLESI
A68: NO | B68: RUC | C68: 20602708731 | D68: LIZGOTEX SAC | E68: 4090340016536 | F68: 45756 | G68: 125 | H68: 45943 | I68: RECURSO EN ANÁLISIS DE FONDO | J68: CARLOS ALFREDO, MALAGA PORTOCARRERO | K68: JUAN CARLOS, CUYA VELARDE | L68: ROBERTO GABRIEL, VERA TUDELA GALLESI
A69: NO | B69: RUC | C69: 20131373237 | D69: MINISTERIO DE SALUD | E69: 4090340016549 | F69: 45756 | G69: 125 | H69: 45943 | I69: RECURSO EN ANÁLISIS DE FONDO | J69: LOURDES FABIOLA, PRETEL NOBLECILLA | K69: ALBERTO ANTHAR, MUNIVE BISETTI | L69: ROBERTO GABRIEL, VERA TUDELA GALLESI
A70: NO | B70: RUC | C70: 20601311781 | D70: RICBEL F.H. LOGISTICA S.A. | E70: 4090340016550 | F70: 45756 | G70: 125 | H70: 45943 | I70: RECURSO EN ANÁLISIS DE FONDO | J70: CECILIA JACQUELINE, ACOSTA SALAZAR | K70: ALBERTO ANTHAR, MUNIVE BISETTI | L70: ROBERTO GABRIEL, VERA TUDELA GALLESI
A71: NO | B71: RUC | C71: 20601776201 | D71: A & G INVERSIONES SELVA E.I.R.L. | E71: 4090340016628 | F71: 45756 | G71: 125 | H71: 45943 | I71: RECURSO EN ANÁLISIS DE FONDO | J71: JOSE WAGNER, LINAREZ AMACIFUEN | K71: ALBERTO ANTHAR, MUNIVE BISETTI | L71: ROBERTO GABRIEL, VERA TUDELA GALLESI
A72: NO | B72: RUC | C72: 10438718422 | D72: BUSTAMANTE DIAZ ROSA DESLY | E72: 4090340016784 | F72: 45756 | G72: 125 | H72: 45943 | I72: RECURSO EN ANÁLISIS DE FONDO | J72: VICTORIA CARMEN ROSA, FLORES ALVITEZ | K72: ALBERTO ANTHAR, MUNIVE BISETTI | L72: ROBERTO GABRIEL, VERA TUDELA GALLESI
...

Sheet Resumen por Resolutor
B2: Producción Agosto 2025
D4: RECLAMOS ATENDIDOS DCC2
B5: REGISTRO | C5: APELLIDO PATERNO | D5: En Q de Expedientes | E5: En Q de Resoluciones | F5: En Q de Expedientes | G5: En Q de Expedientes | H5: En Q de Resoluciones | I5: Total Q de Resoluciones | J5: TOTAL Q de Expedientes
B6: 7342 | C6: JUAN CARLOS, CUYA VELARDE | D6: =+E6 -> 5 | E6: =COUNTIF('Producción Reclamo'!J:J,C6) -> 5 | I6: =E6+H6 -> 5 | J6: =D6+F6+G6 -> 5
B7: 4644 | C7: CARLOS ALFREDO, MALAGA PORTOCARRERO | D7: =+E7+SUMIF('Producción Reclamo'!E1:E1,"=C6") -> 5 | E7: =COUNTIF('Producción Reclamo'!J:J,C7) -> 5 | I7: =E7+H7 -> 5 | J7: =D7+F7+G7 -> 5
B8: AO21 | C8: RENIERD, RIOS GOMEZ | D8: =+E8 -> 10 | E8: =COUNTIF('Producción Reclamo'!J:J,C8) -> 10 | I8: =E8+H8 -> 10 | J8: =D8+F8+G8 -> 10
B9: 7211 | C9: ROBERTO CESAR, RIVAROLA HIDALGO | D9: =+E9 -> 9 | E9: =COUNTIF('Producción Reclamo'!J:J,C9) -> 9 | I9: =E9+H9 -> 9 | J9: =D9+F9+G9 -> 9
B10: 7624 | C10: POUL CRISTIAN, VALDIVIA CHARCA | D10: =+E10 -> 9 | E10: =COUNTIF('Producción Reclamo'!J:J,C10) -> 9 | I10: =E10+H10 -> 9 | J10: =D10+F10+G10 -> 9
B11: 5844 | C11: RICHARD, VELA NUÑEZ | D11: =+E11 -> 10 | E11: =COUNTIF('Producción Reclamo'!J:J,C11) -> 10 | I11: =#REF!+H11 -> #REF! | J11: =E11+F11+G11 -> 10
B12: 2423 | C12: CECILIA JACQUELINE, ACOSTA SALAZAR | D12: =+E12 -> 8 | E12: =COUNTIF('Producción Reclamo'!J:J,C12) -> 8 | J12: =E12+F12+G12 -> 8
B13: 7326 | C13: LYDIA CAROLINA, ARESTEGUI PEREYRA | D13: =+E13 -> 6 | E13: =COUNTIF('Producción Reclamo'!J:J,C13) -> 6
B14: AT75 | C14: VICTORIA CARMEN ROSA, FLORES ALVITEZ | D14: =+E14 -> 15 | E14: =COUNTIF('Producción Reclamo'!J:J,C14) -> 15
B15: 7151 | C15: LOURDES FABIOLA, PRETEL NOBLECILLA | D15: =+E15 -> 9 | E15: =COUNTIF('Producción Reclamo'!J:J,C15) -> 9
B16: 5749 | C16: WILDER ELOY, ULLOA ASCENCIO | D16: =+E16 -> 10 | E16: =COUNTIF('Producción Reclamo'!J:J,C16) -> 10
B17: 4569 | C17: JOSE WAGNER, LINAREZ AMACIFUEN | D17: =+E17 -> 4 | E17: =COUNTIF('Producción Reclamo'!J:J,C17) -> 4
C18: TOTAL | D18: =SUM(D6:D17) -> 100 | E18: =SUM(E6:E17) -> 100 | F18: =SUM(F6:F17) -> 0 | G18: =SUM(G6:G17) -> 0 | H18: =SUM(H6:H17) -> 0 | I18: =SUM(I6:I17) -> #REF! | J18: =SUM(J6:J17) -> 56
B20: Nota: Todos los resolutores adicionalmente realizan labor administrativa, vinculada a a verificación y atención expedientes pendientes en bandeja e chaski (atención de requerimiento de copias, notificaciones), verificación de validez de acuses de notificación; verificación de casos para devolver a admisibilidad, coordinación con admisibilidad y conformación de actuados, reunión TEAMS con unidades en la que se emitiría RD de nulidad, proyección de Memorándum requiriendo actuados a unidades y otros.

Sheet Resumen por Resultado
A1: Resultado Agosto 2025
A3: Etiquetas de fila | B3: Cuenta de Número de Resolución
A4: FUNDADO | B4: 3
A5: INFUNDADO | B5: 83
A6: NULIDAD | B6: 14
A7: Total general | B7: 100

Sheet Producción Reclamo
A1: Indicador de OEA | B1: Tipo de documento | C1: Número documento | D1: Nombre o Razón Social | E1: Número de Expediente | F1: Fecha de Presentación | G1: Plazo vencimiento TLT | H1: Fecha_vencimiento | I1: estado (vencido/no vencido) | J1: Resolutor | K1: Supervisión | L1: División | M1: Número de Resolución | N1: Resultado | O1: Fecha de emisión de RI | P1: Fecha de depósito en SINE
A2: NO | B2: RUC | C2: 10018481788 | D2: MAQUERA CUSACANI ALCIDES | E2: 4090340016816 | F2: 45769 | G2: 125 | H2: 45952 | I2: =IF(H2<O2,"SI","NO") -> NO | J2: CARLOS ALFREDO, MALAGA PORTOCARRERO | K2: JUAN CARLOS, CUYA VELARDE | L2: ROBERTO GABRIEL, VERA TUDELA GALLESI | M2: 4090140015606 | N2: INFUNDADO | O2: 45890 | P2: 45890
A3: NO | B3: RUC | C3: 10018481788 | D3: MAQUERA CUSACANI ALCIDES | E3: 4090340016848 | F3: 45770 | G3: 125 | H3: 45953 | I3: =IF(H3<O3,"SI","NO") -> NO | J3: CARLOS ALFREDO, MALAGA PORTOCARRERO | K3: JUAN CARLOS, CUYA VELARDE | L3: ROBERTO GABRIEL, VERA TUDELA GALLESI | M3: 4090140015688 | N3: INFUNDADO | O3: 45895 | P3: 45895
A4: NO | B4: RUC | C4: 20533054821 | D4: EMPRESA DE TRANSPORTES PACIFICO PULLMAN EMPRESA INDIVIDUAL DE RESPONSABILIDAD LIMITADA | E4: 4090340016871 | F4: 45770 | G4: 125 | H4: 45953 | I4: =IF(H4<O4,"SI","NO") -> NO | J4: CARLOS ALFREDO, MALAGA PORTOCARRERO | K4: JUAN CARLOS, CUYA VELARDE | L4: ROBERTO GABRIEL, VERA TUDELA GALLESI | M4: 4090140015733 | N4: INFUNDADO | O4: 45897 | P4: 45897
A5: NO | B5: RUC | C5: 20533054821 | D5: EMPRESA DE TRANSPORTES PACIFICO PULLMAN EMPRESA INDIVIDUAL DE RESPONSABILIDAD LIMITADA | E5: 4090340016872 | F5: 45770 | G5: 125 | H5: 45953 | I5: =IF(H5<O5,"SI","NO") -> NO | J5: CARLOS ALFREDO, MALAGA PORTOCARRERO | K5: JUAN CARLOS, CUYA VELARDE | L5: ROBERTO GABRIEL, VERA TUDELA GALLESI | M5: 4090140015687 | N5: INFUNDADO | O5: 45895 | P5: 45895
A6: NO | B6: RUC | C6: 20566330068 | D6: ASIX TRADING S.A.C. | E6: 4090340017173 | F6: 45785 | G6: 125 | H6: 45967 | I6: =IF(H6<O6,"SI","NO") -> NO | J6: CARLOS ALFREDO, MALAGA PORTOCARRERO | K6: JUAN CARLOS, CUYA VELARDE | L6: ROBERTO GABRIEL, VERA TUDELA GALLESI | M6: 4090140015788 | N6: INFUNDADO | O6: 45898 | P6: 45898
A7: NO | B7: RUC | C7: 20517510948 | D7: ASKHA LLIMPI S.A.C. | E7: 4090340016200 | F7: 45730 | G7: 125 | H7: 45916 | I7: =IF(H7<O7,"SI","NO") -> NO | J7: CECILIA JACQUELINE, ACOSTA SALAZAR | K7: ALBERTO ANTHAR, MUNIVE BISETTI | L7: ROBERTO GABRIEL, VERA TUDELA GALLESI | M7: 4090140015529 | N7: INFUNDADO | O7: 45882 | P7: 45882
A8: NO | B8: RUC | C8: 20517510948 | D8: ASKHA LLIMPI S.A.C. | E8: 4090340016270 | F8: 45736 | G8: 125 | H8: 45922 | I8: =IF(H8<O8,"SI","NO") -> NO | J8: CECILIA JACQUELINE, ACOSTA SALAZAR | K8: ALBERTO ANTHAR, MUNIVE BISETTI | L8: ROBERTO GABRIEL, VERA TUDELA GALLESI | M8: 4090140015528 | N8: INFUNDADO | O8: 45882 | P8: 45882
A9: NO | B9: RUC | C9: 20517510948 | D9: ASKHA LLIMPI S.A.C. | E9: 4090340016259 | F9: 45736 | G9: 125 | H9: 45922 | I9: =IF(H9<O9,"SI","NO") -> NO | J9: CECILIA JACQUELINE, ACOSTA SALAZAR | K9: ALBERTO ANTHAR, MUNIVE BISETTI | L9: ROBERTO GABRIEL, VERA TUDELA GALLESI | M9: 4090140015527 | N9: INFUNDADO | O9: 45882 | P9: 45882
A10: SI | B10: RUC | C10: 20563297060 | D10: CL ADUANA S.A.C. | E10: 4090340017303 | F10: 45796 | G10: 60 | H10: 45884 | I10: =IF(H10<O10,"SI","NO") -> NO | J10: CECILIA JACQUELINE, ACOSTA SALAZAR | K10: ALBERTO ANTHAR, MUNIVE BISETTI | L10: ROBERTO GABRIEL, VERA TUDELA GALLESI | M10: 4090140015536 | N10: INFUNDADO | O10: 45883 | P10: 45883
A11: NO | B11: RUC | C11: 10084467630 | D11: AGUIRRE VERAMENDI DE BARROS EMERITTA | E11: 4090340015904 | F11: 45697 | G11: 125 | H11: 45881 | I11: =IF(H11<O11,"SI","NO") -> NO | J11: CECILIA JACQUELINE, ACOSTA SALAZAR | K11: ALBERTO ANTHAR, MUNIVE BISETTI | L11: ROBERTO GABRIEL, VERA TUDELA GALLESI | M11: 4090140015503 | N11: INFUNDADO | O11: 45877 | P11: 45877
A12: NO | B12: RUC | C12: 20308430457 | D12: FABRICA DE ENVASES S.A | E12: 4090340016323 | F12: 45699 | G12: 125 | H12: 45883 | I12: =IF(H12<O12,"SI","NO") -> NO | J12: CECILIA JACQUELINE, ACOSTA SALAZAR | K12: ALBERTO ANTHAR, MUNIVE BISETTI | L12: ROBERTO GABRIEL, VERA TUDELA GALLESI | M12: 4090140015538 | N12: INFUNDADO | O12: 45883 | P12: 45883
A13: NO | B13: RUC | C13: 10411270861 | D13: LOPEZ GUEVARA WILDER GUSTAVO | E13: 4090340015724 | F13: 45699 | G13: 125 | H13: 45883 | I13: =IF(H13<O13,"SI","NO") -> NO | J13: CECILIA JACQUELINE, ACOSTA SALAZAR | K13: ALBERTO ANTHAR, MUNIVE BISETTI | L13: ROBERTO GABRIEL, VERA TUDELA GALLESI | M13: 4090140015537 | N13: NULIDAD | O13: 45883 | P13: 45883
... A20: NO | B20: RUC | C20: 20102427891 | D20: TURISMO CIVA S.A.C. | E20: 4090340018949 | F20: 45779 | G20: 125 | H20: 45961 | I20: =IF(H20<O20,"SI","NO") -> NO | J20: JUAN CARLOS, CUYA VELARDE | K20: JUAN CARLOS, CUYA VELARDE | L20: ROBERTO GABRIEL, VERA TUDELA GALLESI | M20: 4090140015790 | N20: NULIDAD | O20: 45898 | P20: 45898
A21: NO | B21: DNI | C21: 31667281 | D21: ZOILO DEDICACION CABANA FIGUEROA | E21: 4090340016900 | F21: 45769 | G21: 125 | H21: 45952 | I21: =IF(H21<O21,"SI","NO") -> NO | J21: JUAN CARLOS, CUYA VELARDE | K21: JUAN CARLOS, CUYA VELARDE | L21: ROBERTO GABRIEL, VERA TUDELA GALLESI | M21: 4090140015794 | N21: NULIDAD | O21: 45898 | P21: SCAD 250286
A22: NO | B22: RUC | C22: 10316672812 | D22: CABANA FIGUEROA ZOILO DEDICACION | E22: 4090340016826 | F22: 45769 | G22: 125 | H22: 45952 | I22: =IF(H22<O22,"SI","NO") -> NO | J22: JUAN CARLOS, CUYA VELARDE | K22: JUAN CARLOS, CUYA VELARDE | L22: ROBERTO GABRIEL, VERA TUDELA GALLESI | M22: 4090140015793 | N22: NULIDAD | O22: 45898 | P22: SCAD 250285
A23: NO | B23: RUC | C23: 10432083158 | D23: RENGIFO BAZAN MILTON FREDY | E23: 4090340016649 | F23: 45749 | G23: 125 | H23: 45933 | I23: =IF(H23<O23,"SI","NO") -> NO | J23: JUAN CARLOS, CUYA VELARDE | K23: JUAN CARLOS, CUYA VELARDE | L23: ROBERTO GABRIEL, VERA TUDELA GALLESI | M23: 4090140015663 | N23: INFUNDADO | O23: 45895 | P23: SCAD 250279
A24: NO | B24: RUC | C24: 20604509077 | D24: ORTOPEDIA TRAUMATOLOGIA Y MEDICINA S.A.C. | E24: 4090340015690 | F24: 45699 | G24: 125 | H24: 45883 | I24: =IF(H24<O24,"SI","NO") -> NO | J24: LOURDES FABIOLA, PRETEL NOBLECILLA | K24: ALBERTO ANTHAR, MUNIVE BISETTI | L24: ROBERTO GABRIEL, VERA TUDELA GALLESI | M24: 4090140015530 | N24: INFUNDADO | O24: 45882 | P24: 45882
A25: NO | B25: RUC | C25: 20384262067 | D25: CORPORACION AMBIENTAL ALANCO PERU S.A.C. - ALANCO PERU S.A.C. | E25: 4090340015725 | F25: 45699 | G25: 125 | H25: 45883 | I25: =IF(H25<O25,"SI","NO") -> NO | J25: LOURDES FABIOLA, PRETEL NOBLECILLA | K25: ALBERTO ANTHAR, MUNIVE BISETTI | L25: ROBERTO GABRIEL, VERA TUDELA GALLESI | M25: 4090140015532 | N25: INFUNDADO | O25: 45882 | P25: 45882
A26: NO | B26: RUC | C26: 10700342641 | D26: AMAYA MECA JHON PAUL | E26: 4090340015985 | F26: 45712 | G26: 125 | H26: 45896 | I26: =IF(H26<O26,"SI","NO") -> NO | J26: LOURDES FABIOLA, PRETEL NOBLECILLA | K26: ALBERTO ANTHAR, MUNIVE BISETTI | L26: ROBERTO GABRIEL, VERA TUDELA GALLESI | M26: 4090140015579 | N26: INFUNDADO | O26: 45888 | P26: 45888
A27: NO | B27: RUC | C27: 20607335801 | D27: MOV STORE E.I.R.L. | E27: 4090340016108 | F27: 45716 | G27: 125 | H27: 45902 | I27: =IF(H27<O27,"SI","NO") -> NO | J27: LOURDES FABIOLA, PRETEL NOBLECILLA | K27: ALBERTO ANTHAR, MUNIVE BISETTI | L27: ROBERTO GABRIEL, VERA TUDELA GALLESI | M27: 4090140015578 | N27: INFUNDADO | O27: 45888 | P27: 45888
A28: NO | B28: RUC | C28: 10731453735 | D28: CALDERON GURBILLON JORGE ALBERTO | E28: 4090340016110 | F28: 45716 | G28: 125 | H28: 45902 | I28: =IF(H28<O28,"SI","NO") -> NO | J28: LOURDES FABIOLA, PRETEL NOBLECILLA | K28: ALBERTO ANTHAR, MUNIVE BISETTI | L28: ROBERTO GABRIEL, VERA TUDELA GALLESI | M28: 4090140015598 | N28: INFUNDADO | O28: 45889 | P28: 45889
A29: NO | B29: RUC | C29: 10488980543 | D29: GARCIA LLEONART RAMON | E29: 4090340016731 | F29: 45763 | G29: 125 | H29: 45950 | I29: =IF(H29<O29,"SI","NO") -> NO | J29: LOURDES FABIOLA, PRETEL NOBLECILLA | K29: ALBERTO ANTHAR, MUNIVE BISETTI | L29: ROBERTO GABRIEL, VERA TUDELA GALLESI | M29: 4090140015650 | N29: INFUNDADO | O29: 45894 | P29: 45894
A30: SI | B30: RUC | C30: 20259880603 | D30: TERPEL COMERCIAL DEL PERU S.R.L. | E30: 4090340017699 | F30: 45818 | G30: 60 | H30: 45908 | I30: =IF(H30<O30,"SI","NO") -> NO | J30: LOURDES FABIOLA, PRETEL NOBLECILLA | K30: ALBERTO ANTHAR, MUNIVE BISETTI | L30: ROBERTO GABRIEL, VERA TUDELA GALLESI | M30: 4090140015604 | N30: FUNDADO | O30: 45890 | P30: 45890
A31: NO | B31: RUC | C31: 10473493603 | D31: VILLEGAS PANTA CESAR IVAN | E31: 4090340016068 | F31: 45698 | G31: 125 | H31: 45882 | I31: =IF(H31<O31,"SI","NO") -> NO | J31: LOURDES FABIOLA, PRETEL NOBLECILLA | K31: ALBERTO ANTHAR, MUNIVE BISETTI | L31: ROBERTO GABRIEL, VERA TUDELA GALLESI | M31: 4090140015509 | N31: INFUNDADO | O31: 45880 | P31: 45880
A32: NO | B32: RUC | C32: 15337718601 | D32: POZO MORA CLEMENTE SILVESTRE | E32: 4090340015979 | F32: 45714 | G32: 125 | H32: 45898 | I32: =IF(H32<O32,"SI","NO") -> NO | J32: LOURDES FABIOLA, PRETEL NOBLECILLA | K32: ALBERTO ANTHAR, MUNIVE BISETTI | L32: ROBERTO GABRIEL, VERA TUDELA GALLESI | M32: 4090140015647 | N32: INFUNDADO | O32: 45894 | P32: 45894
A33: NO | B33: RUC | C33: 20481787743 | D33: AGRO EXPORTACIONES PERU FOODS SAC | E33: 4090340016350 | F33: 45742 | G33: 125 | H33: 45926 | I33: =IF(H33<O33,"SI","NO") -> NO | J33: LYDIA CAROLINA, ARESTEGUI PEREYRA | K33: ALBERTO ANTHAR, MUNIVE BISETTI | L33: ROBERTO GABRIEL, VERA TUDELA GALLESI | M33: 4090140015741 | N33: INFUNDADO | O33: 45897 | P33: 45897
A34: NO | B34: RUC | C34: 20559711960 | D34: TINO EXCAVACIONES PERU S.A.C. | E34: 4090340016358 | F34: 45742 | G34: 125 | H34: 45926 | I34: =IF(H34<O34,"SI","NO") -> NO | J34: LYDIA CAROLINA, ARESTEGUI PEREYRA | K34: ALBERTO ANTHAR, MUNIVE BISETTI | L34: ROBERTO GABRIEL, VERA TUDELA GALLESI | M34: 4090140015740 | N34: INFUNDADO | O34: 45897 | P34: 45897
A35: NO | B35: RUC | C35: 20608673726 | D35: J&M GRUPO TEXTIL E.I.R.L. | E35: 4090340015960 | F35: 45712 | G35: 125 | H35: 45896 | I35: =IF(H35<O35,"SI","NO") -> NO | J35: LYDIA CAROLINA, ARESTEGUI PEREYRA | K35: ALBERTO ANTHAR, MUNIVE BISETTI | L35: ROBERTO GABRIEL, VERA TUDELA GALLESI | M35: 4090140015599 | N35: INFUNDADO | O35: 45889 | P35: 45889
... A73: NO | B73: RUC | C73: 10049607259 | D73: PARI ALLER EDGAR FRANCISCO | E73: 4090340017304 | F73: 45793 | G73: 125 | H73: 45975 | I73: =IF(H73<O73,"SI","NO") -> NO | J73: ROBERTO CESAR, RIVAROLA HIDALGO | K73: JUAN CARLOS, CUYA VELARDE | L73: ROBERTO GABRIEL, VERA TUDELA GALLESI | M73: 4090140015504 | N73: INFUNDADO | O73: 45877 | P73: 45877
A74: NO | B74: DNI | C74: 77014076 | D74: HEBERT MAMANI TEVES | E74: 4090340017692 | F74: 45818 | G74: 125 | H74: 46002 | I74: =IF(H74<O74,"SI","NO") -> NO | J74: ROBERTO CESAR, RIVAROLA HIDALGO | K74: JUAN CARLOS, CUYA VELARDE | L74: ROBERTO GABRIEL, VERA TUDELA GALLESI | M74: 4090140015686 | N74: INFUNDADO | O74: 45895 | P74: SCAD 250280
A75: NO | B75: RUC | C75: 20515521217 | D75: BLOG ADUANAS S.A.C. | E75: 4090340016386 | F75: 45712 | G75: 125 | H75: 45896 | I75: =IF(H75<O75,"SI","NO") -> NO | J75: ROBERTO CESAR, RIVAROLA HIDALGO | K75: JUAN CARLOS, CUYA VELARDE | L75: ROBERTO GABRIEL, VERA TUDELA GALLESI | M75: 4090140015641 | N75: NULIDAD | O75: 45894 | P75: 45894
A76: NO | B76: RUC | C76: 10294730295 | D76: ZEGARRA PINTO JOSE MARIA | E76: 4090340016012 | F76: 45712 | G76: 125 | H76: 45896 | I76: =IF(H76<O76,"SI","NO") -> NO | J76: ROBERTO CESAR, RIVAROLA HIDALGO | K76: JUAN CARLOS, CUYA VELARDE | L76: ROBERTO GABRIEL, VERA TUDELA GALLESI | M76: 4090140015629 | N76: NULIDAD | O76: 45891 | P76: 45891
A77: NO | B77: RUC | C77: 20103913340 | D77: ORVISA SOCIEDAD ANONIMA | E77: 4090340015914 | F77: 45705 | G77: 125 | H77: 45889 | I77: =IF(H77<O77,"SI","NO") -> NO | J77: VICTORIA CARMEN ROSA, FLORES ALVITEZ | K77: ALBERTO ANTHAR, MUNIVE BISETTI | L77: ROBERTO GABRIEL, VERA TUDELA GALLESI | M77: 4090140015568 | N77: INFUNDADO | O77: 45887 | P77: 45887
A78: NO | B78: RUC | C78: 20610193693 | D78: SODI IMPORT SELVA S.A.C. | E78: 4090340016063 | F78: 45714 | G78: 125 | H78: 45898 | I78: =IF(H78<O78,"SI","NO") -> NO | J78: VICTORIA CARMEN ROSA, FLORES ALVITEZ | K78: ALBERTO ANTHAR, MUNIVE BISETTI | L78: ROBERTO GABRIEL, VERA TUDELA GALLESI | M78: 4090140015649 | N78: INFUNDADO | O78: 45894 | P78: 45894
A79: NO | B79: RUC | C79: 20601311331 | D79: NM INDUSTRIAL DEVELOPMENTS S.A.C. | E79: 4090340015718 | F79: 45699 | G79: 125 | H79: 45883 | I79: =IF(H79<O79,"SI","NO") -> NO | J79: VICTORIA CARMEN ROSA, FLORES ALVITEZ | K79: ALBERTO ANTHAR, MUNIVE BISETTI | L79: ROBERTO GABRIEL, VERA TUDELA GALLESI | M79: 4090140015535 | N79: NULIDAD | O79: 45883 | P79: 45883
A80: NO | B80: RUC | C80: 20408998981 | D80: ARMANDO DAVILA ALVARADO EIRL | E80: 4090340015913 | F80: 45706 | G80: 125 | H80: 45890 | I80: =IF(H80<O80,"SI","NO") -> NO | J80: VICTORIA CARMEN ROSA, FLORES ALVITEZ | K80: ALBERTO ANTHAR, MUNIVE BISETTI | L80: ROBERTO GABRIEL, VERA TUDELA GALLESI | M80: 4090140015462 | N80: INFUNDADO | O80: 45870 | P80: 45870
A81: NO | B81: RUC | C81: 20408998981 | D81: ARMANDO DAVILA ALVARADO EIRL | E81: 4090340015916 | F81: 45706 | G81: 125 | H81: 45890 | I81: =IF(H81<O81,"SI","NO") -> NO | J81: VICTORIA CARMEN ROSA, FLORES ALVITEZ | K81: ALBERTO ANTHAR, MUNIVE BISETTI | L81: ROBERTO GABRIEL, VERA TUDELA GALLESI | M81: 4090140015463 | N81: INFUNDADO | O81: 45870 | P81: 45870
A82: NO | B82: RUC | C82: 20408998981 | D82: ARMANDO DAVILA ALVARADO EIRL | E82: 4090340015917 | F82: 45706 | G82: 125 | H82: 45890 | I82: =IF(H82<O82,"SI","NO") -> NO | J82: VICTORIA CARMEN ROSA, FLORES ALVITEZ | K82: ALBERTO ANTHAR, MUNIVE BISETTI | L82: ROBERTO GABRIEL, VERA TUDELA GALLESI | M82: 4090140015464 | N82: INFUNDADO | O82: 45870 | P82: 45870
A83: NO | B83: RUC | C83: 20408998981 | D83: ARMANDO DAVILA ALVARADO EIRL | E83: 4090340015920 | F83: 45706 | G83: 125 | H83: 45890 | I83: =IF(H83<O83,"SI","NO") -> NO | J83: VICTORIA CARMEN ROSA, FLORES ALVITEZ | K83: ALBERTO ANTHAR, MUNIVE BISETTI | L83: ROBERTO GABRIEL, VERA TUDELA GALLESI | M83: 4090140015465 | N83: INFUNDADO | O83: 45870 | P83: 45870
...

Sheet Hoja1
B1: RUC | C1: 10060037456 | D1: VILCHEZ COVEÑAS JULIO | E1: 4090340011045 | F1: 11/07/2024 | I1: MARCO ANTONIO, TREGEAR JIMENEZ | J1: 4840 ALBERTO ANTHAR MUNIVE BISETTI | K1: 5905 ROBERTO GABRIEL VERA TUDELA GALLESI | L1: 4090140010022 | M1: 45565 | N1: 45565
B2: RUC | C2: 20610637273 | D2: PERU ROCKET IMPORTACIONES E.I.R.L. | E2: 4090340010968 | F2: 07/07/2024 | I2: MARCO ANTONIO, TREGEAR JIMENEZ | J2: 4840 ALBERTO ANTHAR MUNIVE BISETTI | K2: 5906 ROBERTO GABRIEL VERA TUDELA GALLESI | L2: 4090140010048 | M2: 45565 | N2: 45565
B3: RUC | C3: 10750756714 | D3: MIRANO PORTOCARRERO JEFERSON | E3: 4090340010715 | F3: 28/06/2024 | I3: MARCO ANTONIO, TREGEAR JIMENEZ | J3: 4840 ALBERTO ANTHAR MUNIVE BISETTI | K3: 5907 ROBERTO GABRIEL VERA TUDELA GALLESI | L3: 4090140010032 | M3: 45565 | N3: 45565
B4: RUC | C4: 10178960721 | D4: GONZALEZ DE AGUIRRE MARTHA YNES | E4: 4090340010586 | F4: 24/06/2024 | I4: MARCO ANTONIO, TREGEAR JIMENEZ | J4: 4840 ALBERTO ANTHAR MUNIVE BISETTI | K4: 5908 ROBERTO GABRIEL VERA TUDELA GALLESI | L4: 4090140009759 | M4: 45541 | N4: 45541
B5: RUC | C5: 20609748347 | D5: GROUP FOUR LOVE INTERNATIONAL S.A.C. | E5: 4090340010799 | F5: 22/06/2024 | I5: MARCO ANTONIO, TREGEAR JIMENEZ | J5: 4840 ALBERTO ANTHAR MUNIVE BISETTI | K5: 5909 ROBERTO GABRIEL VERA TUDELA GALLESI | L5: 4090140009755 | M5: 45541 | N5: 45541
B6: RUC | C6: 20609748347 | D6: GROUP FOUR LOVE INTERNATIONAL S.A.C. | E6: 4090340010610 | F6: 20/06/2024 | I6: MARCO ANTONIO, TREGEAR JIMENEZ | J6: 4840 ALBERTO ANTHAR MUNIVE BISETTI | K6: 5910 ROBERTO GABRIEL VERA TUDELA GALLESI | L6: 4090140009753 | M6: 45540 | N6: 45540
B7: RUC | C7: 10062546498 | D7: MATIAS HUAMAN BERTHA | E7: 4090340010544 | F7: 19/06/2024 | I7: MARCO ANTONIO, TREGEAR JIMENEZ | J7: 4840 ALBERTO ANTHAR MUNIVE BISETTI | K7: 5911 ROBERTO GABRIEL VERA TUDELA GALLESI | L7: 4090140010078 | M7: 45565 | N7: 45565
B8: RUC | C8: 20601311781 | D8: RICBEL F.H. LOGISTICA S.A. | E8: 4090340010306 | F8: 06/06/2024 | I8: MARCO ANTONIO, TREGEAR JIMENEZ | J8: 4840 ALBERTO ANTHAR MUNIVE BISETTI | K8: 5912 ROBERTO GABRIEL VERA TUDELA GALLESI | L8: 4090140009761 | M8: 45541 | N8: 45542
B9: RUC | C9: 10762831649 | D9: TUME PAZO JHUNNIOR SMITH | E9: 4090340010138 | F9: 28/05/2024 | I9: MARCO ANTONIO, TREGEAR JIMENEZ | J9: 4840 ALBERTO ANTHAR MUNIVE BISETTI | K9: 5913 ROBERTO GABRIEL VERA TUDELA GALLESI | L9: 4090140009760 | M9: 45541 | N9: 45545
B10: RUC | C10: 10446350485 | D10: COTERA SANTOS MIRKO JHONN | E10: 4090340010012 | F10: 06/05/2024 | I10: MARCO ANTONIO, TREGEAR JIMENEZ | J10: 4840 ALBERTO ANTHAR MUNIVE BISETTI | K10: 5914 ROBERTO GABRIEL VERA TUDELA GALLESI | L10: 4090140009758 | M10: 45541 | N10: 45544
